[2025-07-07T20:40:58.939+0000] {taskinstance.py:1956} INFO - Dependencies all met for dep_context=non-requeueable deps ti=<TaskInstance: read_titanic_csv.read_csv manual__2025-07-07T20:40:58.085626+00:00 [queued]>
[2025-07-07T20:40:58.945+0000] {taskinstance.py:1956} INFO - Dependencies all met for dep_context=requeueable deps ti=<TaskInstance: read_titanic_csv.read_csv manual__2025-07-07T20:40:58.085626+00:00 [queued]>
[2025-07-07T20:40:58.946+0000] {taskinstance.py:2170} INFO - Starting attempt 1 of 1
[2025-07-07T20:40:58.954+0000] {taskinstance.py:2191} INFO - Executing <Task(PythonOperator): read_csv> on 2025-07-07 20:40:58.085626+00:00
[2025-07-07T20:40:58.958+0000] {standard_task_runner.py:60} INFO - Started process 225 to run task
[2025-07-07T20:40:58.961+0000] {standard_task_runner.py:87} INFO - Running: ['***', 'tasks', 'run', 'read_titanic_csv', 'read_csv', 'manual__2025-07-07T20:40:58.085626+00:00', '--job-id', '4', '--raw', '--subdir', 'DAGS_FOLDER/titanic_dag.py', '--cfg-path', '/tmp/tmp50lsio1p']
[2025-07-07T20:40:58.963+0000] {standard_task_runner.py:88} INFO - Job 4: Subtask read_csv
[2025-07-07T20:40:58.975+0000] {logging_mixin.py:188} WARNING - /home/***/.local/lib/python3.8/site-packages/***/settings.py:194 DeprecationWarning: The sql_alchemy_conn option in [core] has been moved to the sql_alchemy_conn option in [database] - the old setting has been used, but please update your config.
[2025-07-07T20:40:59.018+0000] {task_command.py:423} INFO - Running <TaskInstance: read_titanic_csv.read_csv manual__2025-07-07T20:40:58.085626+00:00 [running]> on host d29533215089
[2025-07-07T20:40:59.079+0000] {taskinstance.py:2480} INFO - Exporting env vars: AIRFLOW_CTX_DAG_OWNER='***' AIRFLOW_CTX_DAG_ID='read_titanic_csv' AIRFLOW_CTX_TASK_ID='read_csv' AIRFLOW_CTX_EXECUTION_DATE='2025-07-07T20:40:58.085626+00:00' AIRFLOW_CTX_TRY_NUMBER='1' AIRFLOW_CTX_DAG_RUN_ID='manual__2025-07-07T20:40:58.085626+00:00'
[2025-07-07T20:40:59.083+0000] {taskinstance.py:2698} ERROR - Task failed with exception
Traceback (most recent call last):
  File "/home/airflow/.local/lib/python3.8/site-packages/airflow/models/taskinstance.py", line 433, in _execute_task
    result = execute_callable(context=context, **execute_callable_kwargs)
  File "/home/airflow/.local/lib/python3.8/site-packages/airflow/operators/python.py", line 199, in execute
    return_value = self.execute_callable()
  File "/home/airflow/.local/lib/python3.8/site-packages/airflow/operators/python.py", line 216, in execute_callable
    return self.python_callable(*self.op_args, **self.op_kwargs)
  File "/opt/airflow/dags/titanic_dag.py", line 7, in read_csv
    df = pd.read_csv('/opt/airflow/data/cleaned_titanic.csv')
  File "/home/airflow/.local/lib/python3.8/site-packages/pandas/io/parsers/readers.py", line 912, in read_csv
    return _read(filepath_or_buffer, kwds)
  File "/home/airflow/.local/lib/python3.8/site-packages/pandas/io/parsers/readers.py", line 577, in _read
    parser = TextFileReader(filepath_or_buffer, **kwds)
  File "/home/airflow/.local/lib/python3.8/site-packages/pandas/io/parsers/readers.py", line 1407, in __init__
    self._engine = self._make_engine(f, self.engine)
  File "/home/airflow/.local/lib/python3.8/site-packages/pandas/io/parsers/readers.py", line 1661, in _make_engine
    self.handles = get_handle(
  File "/home/airflow/.local/lib/python3.8/site-packages/pandas/io/common.py", line 859, in get_handle
    handle = open(
FileNotFoundError: [Errno 2] No such file or directory: '/opt/airflow/data/cleaned_titanic.csv'
[2025-07-07T20:40:59.099+0000] {taskinstance.py:1138} INFO - Marking task as FAILED. dag_id=read_titanic_csv, task_id=read_csv, execution_date=20250707T204058, start_date=20250707T204058, end_date=20250707T204059
[2025-07-07T20:40:59.108+0000] {standard_task_runner.py:107} ERROR - Failed to execute job 4 for task read_csv ([Errno 2] No such file or directory: '/opt/airflow/data/cleaned_titanic.csv'; 225)
[2025-07-07T20:40:59.134+0000] {local_task_job_runner.py:234} INFO - Task exited with return code 1
[2025-07-07T20:40:59.148+0000] {taskinstance.py:3280} INFO - 0 downstream tasks scheduled from follow-on schedule check
